Workbook

Sheet PLANIFICACION
A1: NOMBRE DEL PROYECTO | B1: POSEIDÓN – Sistema Web del Club Náutico Poseidón del Perú
A2: DESCRIPCIÓN: | B2: Sistema web para la gestión de socios, embarcaciones, salidas de naves, facturación y cobranzas del club.
A3: RESPONSABLE DEL PROYECTO | B3: =EQUIPO!$B$7 -> Jose Espinoza Rivadeneira
A5: Épicas | B5: Sprint | C5: Historias de Usuario | D5: Criterios de aceptación | E5: Estado | F5: Tecnologías utilizadas | G5: Inicio y Fin | H5: Recurso Responsable | I5: Release
A6: Home Page y Base del Sistema Web: Establecer la base técnica del proyecto y publicar la página de inicio (Home) del Club Náutico Poseidón del Perú. | B6: 1 | C6: HU01 - Configuración del proyecto y control de versiones Como equipo de desarrollo quiero configurar el proyecto Angular, los estilos y los repositorios para trabajar de forma ordenada y con trazabilidad de cambios. | D6: Proyecto Angular creado con Angular CLI y estructura de carpetas (components, pages, services, assets) | E6: Completado | F6: Angular CLI, TypeScript, Node.js. Bootstrap 5, SCSS. Git, GitHub, Visual Studio Code. Jira (backlog exportado a Excel). | G6: 19/09/26 al 25/09/26 | H6: =EQUIPO!$B$7 -> Jose Espinoza Rivadeneira | I6: Versión 1: Home page y acceso al sistema
B7: 1 | D7: Bootstrap 5 y SCSS configurados, con variables de color y tipografía en un archivo global | E7: Completado
B8: 1 | D8: Repositorio en GitHub con ramas main, develop y feature/*, y todos los integrantes agregados como colaboradores | E8: Completado
B9: 1 | D9: Backlog cargado en Jira y exportado a Excel | E9: Completado
B10: 1 | C10: HU02 - Barra de navegación y pie de página Como visitante quiero una barra de navegación clara y un pie de página para desplazarme fácilmente por el sitio del club. | D10: Navbar con logo y enlaces: Inicio, Nosotros, Servicios, Instalaciones y Contacto | E10: Completado | F10: Angular (componentes navbar y footer, RouterModule). Bootstrap 5 (Navbar), SCSS. | G10: 19/09/26 al 02/10/26 | H10: =EQUIPO!$B$7 -> Jose Espinoza Rivadeneira | I10: Versión 1: Home page y acceso al sistema
B11: 1 | D11: Menú colapsable (hamburguesa) en pantallas pequeñas | E11: En proceso
B12: 1 | D12: Botones "Hazte socio" e "Iniciar sesión" visibles en la barra | E12: Completado
B13: 1 | D13: Footer con datos de contacto, redes sociales y derechos reservados | E13: Completado
B14: 1 | C14: HU03 - Portada de bienvenida (Hero) Como visitante quiero ver una portada atractiva con la propuesta del club para saber de inmediato qué ofrece. | D14: Banner principal con imagen náutica (muelle o embarcaciones) y título de bienvenida | E14: Completado | F14: Angular (componente hero). Bootstrap 5 (grid, botones), SCSS. | G14: 26/09/26 al 02/10/26 | H14: =EQUIPO!$B$7 -> Jose Espinoza Rivadeneira | I14: Versión 1: Home page y acceso al sistema
B15: 1 | D15: Texto breve con la propuesta de valor del club | E15: Completado
B16: 1 | D16: Botones de acción: "Quiero ser socio" y "Conoce nuestros servicios" | E16: Completado
B17: 1 | D17: Imagen optimizada que no afecte la velocidad de carga | E17: Completado
B18: 1 | C18: HU04 - Secciones informativas del club Como visitante quiero conocer el club, sus servicios e instalaciones para decidir si me interesa inscribirme como socio. | D18: Sección "Nosotros" con reseña, misión y visión del club | E18: Completado | F18: Angular (componentes por sección). Bootstrap 5 (cards, grid), SCSS. | G18: 26/09/26 al 02/10/26 | H18: =EQUIPO!$B$8 -> Jack | I18: Versión 1: Home page y acceso al sistema
B19: 1 | D19: Sección "Servicios" en tarjetas: amarre de embarcaciones (rada), limpieza de nave, cabotaje, traslado de nave, cafetería e instructores de natación, navegación y buceo | E19: Completado
B20: 1 | D20: Sección "Instalaciones": piscinas, salones de relajación, cafeterías y salones de fiestas | E20: Completado
B21: 1 | D21: Al hacer clic en el menú, la página se desplaza a la sección correspondiente | E21: En proceso
B22: 1 | C22: HU05 - Contacto y diseño adaptable (responsive) Como visitante quiero contactar al club y ver el sitio correctamente desde mi celular para resolver mis dudas desde cualquier dispositivo. | D22: Sección de contacto con dirección, teléfono, correo y horario de atención | E22: Completado | F22: Angular (Reactive Forms). Bootstrap 5 (grid, breakpoints), SCSS (media queries). | G22: 26/09/26 al 02/10/26 | H22: =EQUIPO!$B$8 -> Jack | I22: Versión 1: Home page y acceso al sistema
B23: 1 | D23: Formulario de consulta con validación de campos (nombre, correo y mensaje) | E23: Completado
B24: 1 | D24: Referencia de ubicación del club (mapa o dirección) | E24: Falta
B25: 1 | D25: Home probado en móvil, tablet y escritorio sin desbordes de contenido | E25: En proceso
A26: Acceso al Sistema y Roles de Usuario: Permitir el ingreso seguro al sistema según el perfil de cada usuario del club. | B26: 2 | C26: HU06 - Inicio de sesión Como usuario del sistema (socio o personal del club) quiero iniciar sesión con mi usuario y contraseña para acceder a las funciones de mi perfil. | D26: Formulario de inicio de sesión con validación de campos obligatorios | E26: Falta | F26: Angular (RouterModule, Guards). Bootstrap 5, SCSS. Datos: API REST (por definir con el equipo). | G26: 03/10/26 al 09/10/26 | H26: =EQUIPO!$B$7 -> Jose Espinoza Rivadeneira | I26: Versión 1: Home page y acceso al sistema
B27: 2 | D27: Mensaje claro cuando las credenciales son incorrectas | E27: Falta
B28: 2 | D28: Sesión persistente y opción de cerrar sesión | E28: Falta
B29: 2 | D29: Recuperación de contraseña mediante correo electrónico | E29: Falta
B30: 2 | C30: HU07 - Roles y permisos Como Gerente General quiero que cada área acceda solo a sus funciones para mantener la seguridad de la información del club. | D30: Roles definidos: Gerente General, Atención al Cliente, Servicios Navieros, Administración y Socio | E30: Falta | F30: Angular (RouterModule, Guards). Bootstrap 5, SCSS. Datos: API REST (por definir con el equipo). | G30: 10/10/26 al 16/10/26 | H30: =EQUIPO!$B$8 -> Jack | I30: Versión 1: Home page y acceso al sistema
B31: 2 | D31: Menú de opciones distinto según el rol del usuario | E31: Falta
B32: 2 | D32: Rutas protegidas (guards) que impiden entrar a pantallas no autorizadas | E32: Falta
B33: 2 | D33: Redirección al panel correspondiente después de iniciar sesión | E33: Falta
A34: Inscripción y Aprobación de Socios: Digitalizar la solicitud, verificación y aprobación de nuevos socios, evitando dobles inscripciones. | B34: 3 | C34: HU08 - Solicitar inscripción como socio Como postulante quiero llenar la solicitud de inscripción en línea para iniciar mi proceso de ingreso al club. | D34: Formulario con datos personales, contacto y documento de identidad | E34: Falta | F34: Angular (Reactive Forms, RouterModule). Bootstrap 5, SCSS. Datos: API REST (por definir con el equipo). | G34: 17/10/26 al 23/10/26 | H34: =EQUIPO!$B$7 -> Jose Espinoza Rivadeneira | I34: Versión 2: Socios, embarcaciones y salidas
B35: 3 | D35: Campo para indicar si posee embarcaciones (no es obligatorio para ser socio) | E35: Falta
B36: 3 | D36: Validación de datos obligatorios y de formato (DNI, correo y teléfono) | E36: Falta
B37: 3 | D37: Constancia de registro de la solicitud con número de seguimiento | E37: Falta
B38: 3 | C38: HU09 - Verificar y clasificar al postulante Como secretaria de Atención al Cliente quiero verificar la solicitud y clasificar al postulante para que solo se acepten socios de tipo "pagador". | D38: Bandeja de solicitudes pendientes de verificación | E38: Falta | F38: Angular (Reactive Forms, RouterModule). Bootstrap 5, SCSS. Datos: API REST (por definir con el equipo). | G38: 17/10/26 al 30/10/26 | H38: =EQUIPO!$B$8 -> Jack | I38: Versión 2: Socios, embarcaciones y salidas
B39: 3 | D39: Alerta automática cuando el documento de identidad ya está registrado (evita la doble inscripción) | E39: Falta
B40: 3 | D40: Registro del resultado de la verificación con otros clubes | E40: Falta
B41: 3 | D41: Clasificación del postulante: pagador, pagador esporádico o renuente a pago | E41: Falta
...

Sheet FASES
A1: FASES DE DESARROLLO
A3: Cada sprint dura 2 semanas, contadas desde el 19/09/26 (inicio del Sprint 1, Home page).
A5: Sprint | B5: Fechas | C5: Épica | D5: Objetivo del sprint | E5: Entregable / Hito | F5: Release
A6: 1 | B6: 19/09/26 al 02/10/26 | C6: Home Page y Base del Sistema Web | D6: Configurar el proyecto (Angular, Bootstrap, SCSS, Git/GitHub) y construir el Home page. | E6: Home page responsive publicado en la rama develop; repositorio con commits de todos los integrantes. | F6: Versión 1: Home page y acceso al sistema
A7: 2 | B7: 03/10/26 al 16/10/26 | C7: Acceso al Sistema y Roles de Usuario | D7: Implementar inicio de sesión y control de acceso por rol. | E7: Login funcional y menús por rol. | F7: Versión 1: Home page y acceso al sistema
A8: 3 | B8: 17/10/26 al 30/10/26 | C8: Inscripción y Aprobación de Socios | D8: Digitalizar la inscripción, verificación y aprobación de socios. | E8: Flujo completo de solicitud → verificación → aprobación/desaprobación. | F8: Versión 2: Socios, embarcaciones y salidas
A9: 4 | B9: 31/10/26 al 13/11/26 | C9: Embarcaciones y Radas | D9: Registrar embarcaciones, verificarlas y asignar radas. | E9: Ficha de embarcación y asignación de rada. | F9: Versión 2: Socios, embarcaciones y salidas
A10: 5 | B10: 14/11/26 al 27/11/26 | C10: Salidas de Embarcaciones | D10: Gestionar permisos de salida y el registro de salidas y retornos. | E10: Solicitud, validación y registro de salidas. | F10: Versión 2: Socios, embarcaciones y salidas
A11: 6 | B11: 28/11/26 al 11/12/26 | C11: Servicios del Club y Facturación | D11: Registrar servicios adicionales y emitir la facturación mensual y diferida. | E11: Recibos mensuales con membresía, rada y servicios. | F11: Versión 3: Facturación, cobranzas y reportes
A12: 7 | B12: 12/12/26 al 25/12/26 | C12: Cobranzas y Retiro de Socios | D12: Registrar pagos, calcular intereses por mora y tramitar retiros con liquidación. | E12: Estado de cuenta, liquidación administrativa y baja de socio. | F12: Versión 3: Facturación, cobranzas y reportes
A13: 8 | B13: 26/12/26 al 08/01/27 | C13: Atención al Cliente y Reportes Gerenciales | D13: Gestionar quejas y ofrecer reportes para la gerencia; cierre y pruebas finales. | E13: Módulo de quejas, panel gerencial y versión final del sistema. | F13: Versión 3: Facturación, cobranzas y reportes

Sheet EQUIPO
A1: EQUIPO DEL PROYECTO
A3: Cómo usar esta hoja: escribe los datos de cada integrante en las celdas amarillas. Los nombres de la columna B se actualizan solos en PLANIFICACION y RESUMEN.
A5: N° | B5: Nombre completo | C5: Rol en el proyecto | D5: Usuario de GitHub | E5: Correo
A6: Ej. | B6: Ana Torres Quispe | C6: Scrum Master y desarrollador | D6: anatorres-dev | E6: ana.torres@correo.com
A7: 1 | B7: Jose Espinoza Rivadeneira | C7: Header, Footer y Hero (Home)
A8: 2 | B8: Jack | C8: Secciones informativas y Contacto (Home)
A12: Nota: el plan está repartido entre 2 integrantes (12 historias de usuario cada uno). En el Sprint 1 (Home page): Jose desarrolla Header, Footer y Hero (HU01-HU03); Jack desarrolla las secciones informativas y Contacto (HU04-HU05). Si el equipo cambia de tamaño, reasigna la columna "Recurso Responsable" en PLANIFICACION (lista desplegable).

Sheet RESUMEN
A1: RESUMEN DE AVANCE
A3: Se calcula automáticamente con la columna Estado de PLANIFICACION (cada fila = un criterio de aceptación).
A5: Avance por sprint
A6: Sprint | B6: Criterios totales | C6: Completado | D6: En proceso | E6: Falta | F6: % avance
A7: 1 | B7: =COUNTIF(PLANIFICACION!$B$6:$B$300,A7) -> 20 | C7: =COUNTIFS(PLANIFICACION!$B$6:$B$300,$A7,PLANIFICACION!$E$6:$E$300,"Completado") -> 16 | D7: =COUNTIFS(PLANIFICACION!$B$6:$B$300,$A7,PLANIFICACION!$E$6:$E$300,"En proceso") -> 3 | E7: =COUNTIFS(PLANIFICACION!$B$6:$B$300,$A7,PLANIFICACION!$E$6:$E$300,"Falta") -> 1 | F7: =IF(B7=0,0,C7/B7) -> 0.8
A8: 2 | B8: =COUNTIF(PLANIFICACION!$B$6:$B$300,A8) -> 8 | C8: =COUNTIFS(PLANIFICACION!$B$6:$B$300,$A8,PLANIFICACION!$E$6:$E$300,"Completado") -> 0 | D8: =COUNTIFS(PLANIFICACION!$B$6:$B$300,$A8,PLANIFICACION!$E$6:$E$300,"En proceso") -> 0 | E8: =COUNTIFS(PLANIFICACION!$B$6:$B$300,$A8,PLANIFICACION!$E$6:$E$300,"Falta") -> 8 | F8: =IF(B8=0,0,C8/B8) -> 0
A9: 3 | B9: =COUNTIF(PLANIFICACION!$B$6:$B$300,A9) -> 13 | C9: =COUNTIFS(PLANIFICACION!$B$6:$B$300,$A9,PLANIFICACION!$E$6:$E$300,"Completado") -> 0 | D9: =COUNTIFS(PLANIFICACION!$B$6:$B$300,$A9,PLANIFICACION!$E$6:$E$300,"En proceso") -> 0 | E9: =COUNTIFS(PLANIFICACION!$B$6:$B$300,$A9,PLANIFICACION!$E$6:$E$300,"Falta") -> 13 | F9: =IF(B9=0,0,C9/B9) -> 0
A10: 4 | B10: =COUNTIF(PLANIFICACION!$B$6:$B$300,A10) -> 12 | C10: =COUNTIFS(PLANIFICACION!$B$6:$B$300,$A10,PLANIFICACION!$E$6:$E$300,"Completado") -> 0 | D10: =COUNTIFS(PLANIFICACION!$B$6:$B$300,$A10,PLANIFICACION!$E$6:$E$300,"En proceso") -> 0 | E10: =COUNTIFS(PLANIFICACION!$B$6:$B$300,$A10,PLANIFICACION!$E$6:$E$300,"Falta") -> 12 | F10: =IF(B10=0,0,C10/B10) -> 0
A11: 5 | B11: =COUNTIF(PLANIFICACION!$B$6:$B$300,A11) -> 12 | C11: =COUNTIFS(PLANIFICACION!$B$6:$B$300,$A11,PLANIFICACION!$E$6:$E$300,"Completado") -> 0 | D11: =COUNTIFS(PLANIFICACION!$B$6:$B$300,$A11,PLANIFICACION!$E$6:$E$300,"En proceso") -> 0 | E11: =COUNTIFS(PLANIFICACION!$B$6:$B$300,$A11,PLANIFICACION!$E$6:$E$300,"Falta") -> 12 | F11: =IF(B11=0,0,C11/B11) -> 0
A12: 6 | B12: =COUNTIF(PLANIFICACION!$B$6:$B$300,A12) -> 12 | C12: =COUNTIFS(PLANIFICACION!$B$6:$B$300,$A12,PLANIFICACION!$E$6:$E$300,"Completado") -> 0 | D12: =COUNTIFS(PLANIFICACION!$B$6:$B$300,$A12,PLANIFICACION!$E$6:$E$300,"En proceso") -> 0 | E12: =COUNTIFS(PLANIFICACION!$B$6:$B$300,$A12,PLANIFICACION!$E$6:$E$300,"Falta") -> 12 | F12: =IF(B12=0,0,C12/B12) -> 0
A13: 7 | B13: =COUNTIF(PLANIFICACION!$B$6:$B$300,A13) -> 12 | C13: =COUNTIFS(PLANIFICACION!$B$6:$B$300,$A13,PLANIFICACION!$E$6:$E$300,"Completado") -> 0 | D13: =COUNTIFS(PLANIFICACION!$B$6:$B$300,$A13,PLANIFICACION!$E$6:$E$300,"En proceso") -> 0 | E13: =COUNTIFS(PLANIFICACION!$B$6:$B$300,$A13,PLANIFICACION!$E$6:$E$300,"Falta") -> 12 | F13: =IF(B13=0,0,C13/B13) -> 0
A14: 8 | B14: =COUNTIF(PLANIFICACION!$B$6:$B$300,A14) -> 8 | C14: =COUNTIFS(PLANIFICACION!$B$6:$B$300,$A14,PLANIFICACION!$E$6:$E$300,"Completado") -> 0 | D14: =COUNTIFS(PLANIFICACION!$B$6:$B$300,$A14,PLANIFICACION!$E$6:$E$300,"En proceso") -> 0 | E14: =COUNTIFS(PLANIFICACION!$B$6:$B$300,$A14,PLANIFICACION!$E$6:$E$300,"Falta") -> 8 | F14: =IF(B14=0,0,C14/B14) -> 0
A15: TOTAL | B15: =SUM(B7:B14) -> 97 | C15: =SUM(C7:C14) -> 16 | D15: =SUM(D7:D14) -> 3 | E15: =SUM(E7:E14) -> 78 | F15: =IF(B15=0,0,C15/B15) -> 0.16494845
A18: Historias de usuario por integrante
A19: Integrante | B19: HU asignadas | C19: HU en Sprint 1 | D19: % del total
A20: =EQUIPO!$B$7 -> Jose Espinoza Rivadeneira | B20: =COUNTIF(PLANIFICACION!$H$6:$H$300,A20) -> 12 | C20: =COUNTIFS(PLANIFICACION!$H$6:$H$300,A20,PLANIFICACION!$B$6:$B$300,1) -> 3 | D20: =IF($B$22=0,0,B20/$B$22) -> 0.5
A21: =EQUIPO!$B$8 -> Jack | B21: =COUNTIF(PLANIFICACION!$H$6:$H$300,A21) -> 12 | C21: =COUNTIFS(PLANIFICACION!$H$6:$H$300,A21,PLANIFICACION!$B$6:$B$300,1) -> 2 | D21: =IF($B$22=0,0,B21/$B$22) -> 0.5
A22: TOTAL | B22: =SUM(B20:B21) -> 24 | C22: =SUM(C20:C21) -> 5 | D22: =SUM(D20:D21) -> 1
